#VRML_SIM R2023b utf8

EXTERNPROTO "https://raw.githubusercontent.com/cyberbotics/webots/R2023b/projects/objects/backgrounds/protos/TexturedBackground.proto"
EXTERNPROTO "https://raw.githubusercontent.com/cyberbotics/webots/R2023b/projects/objects/backgrounds/protos/TexturedBackgroundLight.proto"
EXTERNPROTO "https://raw.githubusercontent.com/cyberbotics/webots/R2023b/projects/objects/floors/protos/RectangleArena.proto"
EXTERNPROTO "https://raw.githubusercontent.com/cyberbotics/webots/R2023b/projects/appearances/protos/Parquetry.proto"
IMPORTABLE EXTERNPROTO "../protos/dynamic_objects.proto"

WorldInfo {
}
Viewpoint {
  orientation -0.48270251184970375 0.47909643359448173 0.7331199713355483 1.883521446264484
  position 0.067708431099477 -2.5505724135083487 5.559917736998769
}
TexturedBackground {
}
TexturedBackgroundLight {
}
RectangleArena {
  floorSize 3 3
  floorAppearance Parquetry {
    type "light strip"
    colorOverride 0.56 0.66 0.7
    IBLStrength 11
  }
  wallHeight 0.5
}
Solid {
  translation -0.4 0.69 0.28
  children [
    Shape {
      appearance PBRAppearance {
        baseColor 0.333333 0.666667 0
        metalness 0.2
      }
      geometry Sphere {
        radius 0.05
      }
    }
  ]
}
Solid {
  translation 1.17 1.21 0.28
  children [
    Shape {
      appearance PBRAppearance {
        baseColor 0.333333 0.666667 0
        metalness 0.2
      }
      geometry Sphere {
        radius 0.05
      }
    }
  ]
  name "solid(3)"
}
Solid {
  translation 0.9 -0.74 0.28
  children [
    Shape {
      appearance PBRAppearance {
        baseColor 0.333333 0.666667 0
        metalness 0.2
      }
      geometry Sphere {
        radius 0.05
      }
    }
  ]
  name "solid(2)"
}
Solid {
  translation -0.94 -0.65 0.28
  children [
    Shape {
      appearance PBRAppearance {
        baseColor 0.333333 0.666667 0
        metalness 0.2
      }
      geometry Sphere {
        radius 0.05
      }
    }
  ]
  name "solid(1)"
}
Solid {
  translation -0.16 0.1 0.05
  children [
    Shape {
      appearance PBRAppearance {
      }
      geometry Cylinder {
        height 0.1
        radius 0.05
      }
    }
  ]
  name "obstacle"
  boundingObject Cylinder {
    height 0.1
    radius 0.05
  }
}
Solid {
  translation -0.86 0.13 0.05
  children [
    Shape {
      appearance PBRAppearance {
      }
      geometry Cylinder {
        height 0.1
        radius 0.05
      }
    }
  ]
  name "obstacle(7)"
  boundingObject Cylinder {
    height 0.1
    radius 0.05
  }
}
Solid {
  translation -0.04 -0.11 0.05
  children [
    Shape {
      appearance PBRAppearance {
      }
      geometry Cylinder {
        height 0.1
        radius 0.05
      }
    }
  ]
  name "obstacle(8)"
  boundingObject Cylinder {
    height 0.1
    radius 0.05
  }
}
Solid {
  translation -0.32 0.43 0.05
  children [
    Shape {
      appearance PBRAppearance {
      }
      geometry Cylinder {
        height 0.1
        radius 0.05
      }
    }
  ]
  name "obstacle(9)"
  boundingObject Cylinder {
    height 0.1
    radius 0.05
  }
}
Solid {
  translation 1.13 0.82 0.05
  children [
    Shape {
      appearance PBRAppearance {
      }
      geometry Cylinder {
        height 0.1
        radius 0.05
      }
    }
  ]
  name "obstacle(10)"
  boundingObject Cylinder {
    height 0.1
    radius 0.05
  }
}
Solid {
  translation -1.04 -0.5 0.05
  children [
    Shape {
      appearance PBRAppearance {
      }
      geometry Cylinder {
        height 0.1
        radius 0.05
      }
    }
  ]
  name "obstacle(11)"
  boundingObject Cylinder {
    height 0.1
    radius 0.05
  }
}
Solid {
  translation 0.89 -0.5 0.05
  children [
    Shape {
      appearance PBRAppearance {
      }
      geometry Cylinder {
        height 0.1
        radius 0.05
      }
    }
  ]
  name "obstacle(12)"
  boundingObject Cylinder {
    height 0.1
    radius 0.05
  }
}
Solid {
  translation 0.76 0.92 0.05
  children [
    Shape {
      appearance PBRAppearance {
      }
      geometry Cylinder {
        height 0.1
        radius 0.05
      }
    }
  ]
  name "obstacle(3)"
  boundingObject Cylinder {
    height 0.1
    radius 0.05
  }
}
Solid {
  translation 0.4 -0.86 0.05
  children [
    Shape {
      appearance PBRAppearance {
      }
      geometry Cylinder {
        height 0.1
        radius 0.05
      }
    }
  ]
  name "obstacle(4)"
  boundingObject Cylinder {
    height 0.1
    radius 0.05
  }
}
Solid {
  translation 0.01 -1 0.05
  children [
    Shape {
      appearance PBRAppearance {
      }
      geometry Cylinder {
        height 0.1
        radius 0.05
      }
    }
  ]
  name "obstacle(13)"
  boundingObject Cylinder {
    height 0.1
    radius 0.05
  }
}
Solid {
  translation -1.24 -0.95 0.05
  children [
    Shape {
      appearance PBRAppearance {
      }
      geometry Cylinder {
        height 0.1
        radius 0.05
      }
    }
  ]
  name "obstacle(14)"
  boundingObject Cylinder {
    height 0.1
    radius 0.05
  }
}
Solid {
  translation 1.13 -0.78 0.05
  children [
    Shape {
      appearance PBRAppearance {
      }
      geometry Cylinder {
        height 0.1
        radius 0.05
      }
    }
  ]
  name "obstacle(15)"
  boundingObject Cylinder {
    height 0.1
    radius 0.05
  }
}
Solid {
  translation 0.93 -1.15 0.05
  children [
    Shape {
      appearance PBRAppearance {
      }
      geometry Cylinder {
        height 0.1
        radius 0.05
      }
    }
  ]
  name "obstacle(16)"
  boundingObject Cylinder {
    height 0.1
    radius 0.05
  }
}
Solid {
  translation -0.27 1.13 0.05
  children [
    Shape {
      appearance PBRAppearance {
      }
      geometry Cylinder {
        height 0.1
        radius 0.05
      }
    }
  ]
  name "obstacle(17)"
  boundingObject Cylinder {
    height 0.1
    radius 0.05
  }
}
Solid {
  translation -0.82 0.75 0.05
  children [
    Shape {
      appearance PBRAppearance {
      }
      geometry Cylinder {
        height 0.1
        radius 0.05
      }
    }
  ]
  name "obstacle(18)"
  boundingObject Cylinder {
    height 0.1
    radius 0.05
  }
}
Solid {
  translation 0.29 -0.39 0.05
  children [
    Shape {
      appearance PBRAppearance {
      }
      geometry Cylinder {
        height 0.1
        radius 0.05
      }
    }
  ]
  name "obstacle(19)"
  boundingObject Cylinder {
    height 0.1
    radius 0.05
  }
}
Solid {
  translation -0.62 -0.66 0.05
  children [
    Shape {
      appearance PBRAppearance {
      }
      geometry Cylinder {
        height 0.1
        radius 0.05
      }
    }
  ]
  name "obstacle(5)"
  boundingObject Cylinder {
    height 0.1
    radius 0.05
  }
}
Solid {
  translation 0.61 0.33 0.05
  children [
    Shape {
      appearance PBRAppearance {
      }
      geometry Cylinder {
        height 0.1
        radius 0.05
      }
    }
  ]
  name "obstacle(6)"
  boundingObject Cylinder {
    height 0.1
    radius 0.05
  }
}
Solid {
  translation 1.04 0 0.05
  children [
    Shape {
      appearance PBRAppearance {
      }
      geometry Cylinder {
        height 0.1
        radius 0.05
      }
    }
  ]
  name "obstacle(1)"
  boundingObject Cylinder {
    height 0.1
    radius 0.05
  }
}
Solid {
  translation 0 0.76 0.05
  children [
    Shape {
      appearance PBRAppearance {
      }
      geometry Cylinder {
        height 0.1
        radius 0.05
      }
    }
  ]
  name "obstacle(2)"
  boundingObject Cylinder {
    height 0.1
    radius 0.05
  }
}
Robot {
  translation 0.143074 -0.283846 0.0502919
  rotation 0.0003119583545867591 0.000522679011923945 0.9999998147443006 2.1194532121096814
  children [
    TouchSensor {
      translation 0 0.083 -0.03
      children [
        Shape {
          geometry DEF BUMPER Box {
            size 0.01 0.01 0.01
          }
        }
      ]
      name "bumper_front"
      boundingObject USE BUMPER
    }
    TouchSensor {
      translation -0.0335 0.0659289 -0.03
      rotation 0 0 1 0.785398
      children [
        Shape {
          geometry DEF BUMPER Box {
            size 0.01 0.01 0.01
          }
        }
      ]
      name "bumper_left"
      boundingObject USE BUMPER
    }
    TouchSensor {
      translation 0.0335 0.065929 -0.03
      rotation 0 0 1 -0.785395307179586
      children [
        Shape {
          geometry DEF BUMPER Box {
            size 0.01 0.01 0.01
          }
        }
      ]
      name "bumper_right"
      boundingObject USE BUMPER
    }
    Compass {
      translation 0 0.04 0
    }
    GPS {
      translation 0 0.04 0.001
      children [
        Shape {
          appearance PBRAppearance {
          }
          geometry Capsule {
            height 0.005
            radius 0.005
          }
        }
      ]
    }
    DEF distance_sensor DistanceSensor {
      translation 0 0.0845 -0.01
      rotation 0.5773489358556708 0.5773509358554485 0.5773509358554485 2.0944
      children [
        DEF shape_distance_sensor Shape {
          appearance PBRAppearance {
            baseColor 0 0 1
            metalness 0
          }
          geometry Box {
            size 0.005 0.005 0.005
          }
        }
      ]
      name "d_front"
      boundingObject Box {
        size 0.005 0.005 0.005
      }
      lookupTable [
        0 0 0
        0.22 1000 0
      ]
      numberOfRays 2
      aperture 0.25
    }
    DEF distance_sensor DistanceSensor {
      translation 0.0300001 0.0745003 -0.01
      rotation 0.5773489358556708 0.5773509358554485 0.5773509358554485 2.0944
      children [
        DEF shape_distance_sensor Shape {
          appearance PBRAppearance {
            baseColor 0 0 1
            metalness 0
          }
          geometry Box {
            size 0.005 0.005 0.005
          }
        }
      ]
      name "d_right"
      boundingObject Box {
        size 0.005 0.005 0.005
      }
      lookupTable [
        0 0 0
        0.22 1000 0
      ]
      numberOfRays 2
      aperture 0.25
    }
    DEF distance_sensor DistanceSensor {
      translation 0.0450002 0.0445004 -0.00999996
      rotation 0.5773489358556708 0.5773509358554485 0.5773509358554485 1.98
      children [
        DEF shape_distance_sensor Shape {
          appearance PBRAppearance {
            baseColor 0 0 1
            metalness 0
          }
          geometry Box {
            size 0.005 0.005 0.005
          }
        }
      ]
      name "d_far_right"
      boundingObject Box {
        size 0.005 0.005 0.005
      }
      lookupTable [
        0 0 0
        0.18 1000 0
      ]
      numberOfRays 2
      aperture 0.25
    }
    DEF distance_sensor DistanceSensor {
      translation -0.03 0.0744999 -0.00999999
      rotation -0.5773489358556708 -0.5773509358554485 -0.5773509358554485 -2.094395307179586
      children [
        DEF shape_distance_sensor Shape {
          appearance PBRAppearance {
            baseColor 0 0 1
            metalness 0
          }
          geometry Box {
            size 0.005 0.005 0.005
          }
        }
      ]
      name "d_left"
      boundingObject Box {
        size 0.005 0.005 0.005
      }
      lookupTable [
        0 0 0
        0.22 1000 0
      ]
      numberOfRays 2
      aperture 0.25
    }
    DEF distance_sensor DistanceSensor {
      translation -0.045 0.0444999 -0.00999997
      rotation -0.5773489358556708 -0.5773509358554485 -0.5773509358554485 -2.2
      children [
        DEF shape_distance_sensor Shape {
          appearance PBRAppearance {
            baseColor 0 0 1
            metalness 0
          }
          geometry Box {
            size 0.005 0.005 0.005
          }
        }
      ]
      name "d_far_left"
      boundingObject Box {
        size 0.005 0.005 0.005
      }
      lookupTable [
        0 0 0
        0.18 1000 0
      ]
      numberOfRays 2
      aperture 0.25
    }
    Solid {
      translation 0 0.04 0.001
      rotation 0 0 1 1.5708
      children [
        USE shape_distance_sensor
      ]
      name "solid(2)"
    }
    DEF BodyShapeWithTransform Pose {
      translation 0 0.0415 -0.0176
      children [
        DEF Body Shape {
          appearance PBRAppearance {
            baseColor 1 0 0
            roughness 1
            metalness 0
          }
          geometry Cylinder {
            height 0.04
            radius 0.045
          }
        }
      ]
    }
    DEF wheel_joint HingeJoint {
      jointParameters HingeJointParameters {
        position 0.5402766816202466
        axis -1 0 0
        anchor -0.033 0.0425 -0.0353343
      }
      device [
        RotationalMotor {
          name "motor_1"
        }
      ]
      endPoint Solid {
        translation -0.033 0.0425 -0.0353343
        rotation -0.4313796348121546 0.7923532045845588 0.4313791949710977 4.4817153235467675
        children [
          DEF shape_wheel Shape {
            appearance PBRAppearance {
              baseColor 0 0 1
              roughness 1
              metalness 0
            }
            geometry Cylinder {
              height 0.015
              radius 0.015
            }
          }
        ]
        boundingObject USE shape_wheel
        physics DEF wheel_physics Physics {
        }
      }
    }
    DEF wheel_joint HingeJoint {
      jointParameters HingeJointParameters {
        position 0.09465112631075122
        axis -1 0 0
        anchor 0.033 0.0425 -0.0353343
      }
      device [
        RotationalMotor {
          name "motor_2"
        }
      ]
      endPoint Solid {
        translation 0.033 0.0425 -0.0353343
        rotation -0.10513420162821303 0.9888850397472894 0.10513409443182586 4.7012130396600895
        children [
          DEF shape_wheel Shape {
            appearance PBRAppearance {
              baseColor 0 0 1
              roughness 1
              metalness 0
            }
            geometry Cylinder {
              height 0.015
              radius 0.015
            }
          }
        ]
        name "solid(1)"
        boundingObject USE shape_wheel
        physics USE wheel_physics
      }
    }
    DEF wheel_joint HingeJoint {
      jointParameters HingeJointParameters {
        position 0.31736181497573634
        axis -1 0 0
        anchor -3.58483e-05 0.0104238 -0.0397
      }
      device [
        RotationalMotor {
          name "motor_3"
        }
      ]
      endPoint Solid {
        translation -3.58483e-05 0.0104238 -0.0397
        rotation -0.15607942181598494 -0.9753350592736765 0.15607926267509778 1.5957669282660805
        children [
          DEF shape_wheel Shape {
            appearance PBRAppearance {
              baseColor 0 0 1
              roughness 1
              metalness 0
            }
            geometry Cylinder {
              height 0.005
              radius 0.0105
            }
          }
        ]
        name "solid(3)"
        boundingObject USE shape_wheel
        physics USE wheel_physics
      }
    }
    DEF wheel_joint HingeJoint {
      jointParameters HingeJointParameters {
        position 0.3173618147990532
        axis -1 0 0
        anchor 0 0.075 -0.0397
      }
      device [
        RotationalMotor {
          name "motor_4"
        }
      ]
      endPoint Solid {
        translation 3.728089999999995e-05 0.07490641889324093 -0.03966926197049666
        rotation -0.15607942370805591 -0.9753350586681141 0.1560792645671669 1.5957669288867626
        children [
          DEF shape_wheel Shape {
            appearance PBRAppearance {
              baseColor 0 0 1
              roughness 1
              metalness 0
            }
            geometry Cylinder {
              height 0.005
              radius 0.0105
            }
          }
        ]
        name "solid(4)"
        boundingObject USE shape_wheel
        physics USE wheel_physics
      }
    }
  ]
  boundingObject USE BodyShapeWithTransform
  physics Physics {
    density -1
    mass 1
  }
  controller "test_robot_controller_w0"
}
