#VRML_SIM R2023b utf8

EXTERNPROTO "https://raw.githubusercontent.com/cyberbotics/webots/R2023b/projects/objects/backgrounds/protos/TexturedBackground.proto"
EXTERNPROTO "https://raw.githubusercontent.com/cyberbotics/webots/R2023b/projects/objects/backgrounds/protos/TexturedBackgroundLight.proto"
EXTERNPROTO "https://raw.githubusercontent.com/cyberbotics/webots/R2023b/projects/objects/floors/protos/RectangleArena.proto"
EXTERNPROTO "https://raw.githubusercontent.com/cyberbotics/webots/R2023b/projects/appearances/protos/Parquetry.proto"

WorldInfo {
}
Viewpoint {
  orientation -0.5745929173079156 0.5752788326485498 0.5821488160995442 2.109568091092092
  position 0.20342601702378627 0.03127809602584164 6.674085728292341
}
TexturedBackground {
}
TexturedBackgroundLight {
}
RectangleArena {
  floorSize 3 3
  floorAppearance Parquetry {
    type "light strip"
    colorOverride 0.56 0.66 0.7
    IBLStrength 11
  }
  wallHeight 0.5
}
Solid {
  translation 0.17 -0.06 0.26
  children [
    Shape {
      appearance Appearance {
        material Material {
          diffuseColor 0.282353 1 0.282353
        }
      }
      geometry Sphere {
        radius 0.07
      }
    }
  ]
  name "solid(18)"
  boundingObject Sphere {
    radius 0.07
  }
}
Solid {
  translation -0.52 0.89 0.26
  children [
    Shape {
      appearance Appearance {
        material Material {
          diffuseColor 0.282353 1 0.282353
        }
      }
      geometry Sphere {
        radius 0.07
      }
    }
  ]
  name "solid(24)"
  boundingObject Sphere {
    radius 0.07
  }
}
Solid {
  translation 0.43 -1.15 0.26
  children [
    Shape {
      appearance Appearance {
        material Material {
          diffuseColor 0.282353 0.282353 0.282353
        }
      }
      geometry Sphere {
        radius 0.07
      }
    }
    Shape {
      appearance Appearance {
        material Material {
          diffuseColor 0.282353 1 0.282353
        }
      }
      geometry Sphere {
        radius 0.07
      }
    }
  ]
  name "solid(25)"
  boundingObject Sphere {
    radius 0.07
  }
}
Solid {
  translation -0.89 -0.47 0.26
  children [
    Shape {
      appearance Appearance {
        material Material {
          diffuseColor 0.282353 0.282353 0.282353
        }
      }
      geometry Sphere {
        radius 0.07
      }
    }
    Shape {
      appearance Appearance {
        material Material {
          diffuseColor 0.282353 1 0.282353
        }
      }
      geometry Sphere {
        radius 0.07
      }
    }
  ]
  name "solid(26)"
  boundingObject Sphere {
    radius 0.07
  }
}
Solid {
  translation 0.78 1.06 0.26
  children [
    Shape {
      appearance Appearance {
        material Material {
          diffuseColor 0.282353 0.282353 0.282353
        }
      }
      geometry Sphere {
        radius 0.07
      }
    }
    Shape {
      appearance Appearance {
        material Material {
          diffuseColor 0.282353 1 0.282353
        }
      }
      geometry Sphere {
        radius 0.07
      }
    }
  ]
  name "solid(27)"
  boundingObject Sphere {
    radius 0.07
  }
}
Solid {
  translation -0.93 0.58 0
  children [
    Shape {
      appearance Appearance {
        material Material {
          diffuseColor 0.101961 0.101961 0.101961
          emissiveColor 0.101961 0.101961 0.101961
        }
      }
      geometry Cylinder {
        height 0.3
        radius 0.09
      }
    }
  ]
  boundingObject Cylinder {
    height 0.3
    radius 0.09
  }
}
Solid {
  translation -0.02 0.21 0
  children [
    Shape {
      appearance Appearance {
        material Material {
          diffuseColor 0.101961 0.101961 0.101961
          emissiveColor 0.101961 0.101961 0.101961
        }
      }
      geometry Cylinder {
        height 0.3
        radius 0.09
      }
    }
  ]
  name "solid(8)"
  boundingObject Cylinder {
    height 0.3
    radius 0.09
  }
}
Solid {
  translation -1.23 1.05 0
  children [
    Shape {
      appearance Appearance {
        material Material {
          diffuseColor 0.101961 0.101961 0.101961
          emissiveColor 0.101961 0.101961 0.101961
        }
      }
      geometry Cylinder {
        height 0.2
        radius 0.05
      }
    }
  ]
  name "solid(9)"
  boundingObject Cylinder {
    height 0.2
    radius 0.05
  }
}
Solid {
  translation 0.68 0.58 0
  children [
    Shape {
      appearance Appearance {
        material Material {
          diffuseColor 0.101961 0.101961 0.101961
          emissiveColor 0.101961 0.101961 0.101961
        }
      }
      geometry Cylinder {
        height 0.2
        radius 0.05
      }
    }
  ]
  name "solid(14)"
  boundingObject Cylinder {
    height 0.2
    radius 0.05
  }
}
Solid {
  translation -0.51 -0.99 0
  children [
    Shape {
      appearance Appearance {
        material Material {
          diffuseColor 0.101961 0.101961 0.101961
          emissiveColor 0.101961 0.101961 0.101961
        }
      }
      geometry Cylinder {
        height 0.2
        radius 0.05
      }
    }
  ]
  name "solid(15)"
  boundingObject Cylinder {
    height 0.2
    radius 0.05
  }
}
Solid {
  translation 0.33 -0.74 0
  children [
    Shape {
      appearance Appearance {
        material Material {
          diffuseColor 0.101961 0.101961 0.101961
          emissiveColor 0.101961 0.101961 0.101961
        }
      }
      geometry Cylinder {
        height 0.2
        radius 0.05
      }
    }
  ]
  name "solid(16)"
  boundingObject Cylinder {
    height 0.2
    radius 0.05
  }
}
Solid {
  translation 0.21 0.77 0
  children [
    Shape {
      appearance Appearance {
        material Material {
          diffuseColor 0.101961 0.101961 0.101961
          emissiveColor 0.101961 0.101961 0.101961
        }
      }
      geometry Cylinder {
        height 0.2
        radius 0.05
      }
    }
  ]
  name "solid(17)"
  boundingObject Cylinder {
    height 0.2
    radius 0.05
  }
}
Solid {
  translation 1.28 -0.9 0
  children [
    Shape {
      appearance Appearance {
        material Material {
          diffuseColor 0.101961 0.101961 0.101961
          emissiveColor 0.101961 0.101961 0.101961
        }
      }
      geometry Cylinder {
        height 0.2
        radius 0.05
      }
    }
  ]
  name "solid(19)"
  boundingObject Cylinder {
    height 0.2
    radius 0.05
  }
}
Solid {
  translation -0.51 0.12 0
  children [
    Shape {
      appearance Appearance {
        material Material {
          diffuseColor 0.101961 0.101961 0.101961
          emissiveColor 0.101961 0.101961 0.101961
        }
      }
      geometry Cylinder {
        height 0.4
        radius 0.06
      }
    }
  ]
  name "solid(20)"
  boundingObject Cylinder {
    height 0.4
    radius 0.06
  }
}
Solid {
  translation 1.06 1.34 0
  children [
    Shape {
      appearance Appearance {
        material Material {
          diffuseColor 0.101961 0.101961 0.101961
          emissiveColor 0.101961 0.101961 0.101961
        }
      }
      geometry Cylinder {
        height 0.4
        radius 0.06
      }
    }
  ]
  name "solid(13)"
  boundingObject Cylinder {
    height 0.4
    radius 0.06
  }
}
Solid {
  translation -1.32 -0.98 0
  children [
    Shape {
      appearance Appearance {
        material Material {
          diffuseColor 0.101961 0.101961 0.101961
          emissiveColor 0.101961 0.101961 0.101961
        }
      }
      geometry Cylinder {
        height 0.4
        radius 0.06
      }
    }
  ]
  name "solid(21)"
  boundingObject Cylinder {
    height 0.4
    radius 0.06
  }
}
Solid {
  translation -0.51 1.36 0
  children [
    Shape {
      appearance Appearance {
        material Material {
          diffuseColor 0.101961 0.101961 0.101961
          emissiveColor 0.101961 0.101961 0.101961
        }
      }
      geometry Cylinder {
        height 0.4
        radius 0.06
      }
    }
  ]
  name "solid(22)"
  boundingObject Cylinder {
    height 0.4
    radius 0.06
  }
}
Solid {
  translation 1.25 -0.33 0
  children [
    Shape {
      appearance Appearance {
        material Material {
          diffuseColor 0.101961 0.101961 0.101961
          emissiveColor 0.101961 0.101961 0.101961
        }
      }
      geometry Cylinder {
        height 0.4
        radius 0.06
      }
    }
  ]
  name "solid(23)"
  boundingObject Cylinder {
    height 0.4
    radius 0.06
  }
}
Solid {
  translation -1.16 -0.04 0
  children [
    Shape {
      appearance Appearance {
        material Material {
          diffuseColor 0.101961 0.101961 0.101961
          emissiveColor 0.101961 0.101961 0.101961
        }
      }
      geometry Cylinder {
        height 0.2
        radius 0.05
      }
    }
  ]
  name "solid(11)"
  boundingObject Cylinder {
    height 0.2
    radius 0.05
  }
}
Solid {
  translation 0.9 0.44 0
  children [
    Shape {
      appearance Appearance {
        material Material {
          diffuseColor 0.101961 0.101961 0.101961
          emissiveColor 0.101961 0.101961 0.101961
        }
      }
      geometry Cylinder {
        height 0.2
        radius 0.05
      }
    }
  ]
  name "solid(12)"
  boundingObject Cylinder {
    height 0.2
    radius 0.05
  }
}
Solid {
  translation -0.93 0.58 0
  children [
    Shape {
      appearance Appearance {
        material Material {
          diffuseColor 0.101961 0.101961 0.101961
          emissiveColor 0.101961 0.101961 0.101961
        }
      }
      geometry Cylinder {
        height 0.3
        radius 0.09
      }
    }
  ]
  name "solid(10)"
  boundingObject Cylinder {
    height 0.3
    radius 0.09
  }
}
Solid {
  translation 0.68 -0.23 0
  children [
    Shape {
      appearance Appearance {
        material Material {
          diffuseColor 0.101961 0.101961 0.101961
          emissiveColor 0.101961 0.101961 0.101961
        }
      }
      geometry Cylinder {
        height 0.3
        radius 0.09
      }
    }
  ]
  name "solid(1)"
  boundingObject Cylinder {
    height 0.3
    radius 0.09
  }
}
Solid {
  translation -0.29 -0.54 0
  children [
    Shape {
      appearance Appearance {
        material Material {
          diffuseColor 0.101961 0.101961 0.101961
          emissiveColor 0.101961 0.101961 0.101961
        }
      }
      geometry Cylinder {
        height 0.3
        radius 0.09
      }
    }
  ]
  name "solid(2)"
  boundingObject Cylinder {
    height 0.3
    radius 0.09
  }
}
Solid {
  translation 0.08 1.02 0
  children [
    Shape {
      appearance Appearance {
        material Material {
          diffuseColor 0.101961 0.101961 0.101961
          emissiveColor 0.101961 0.101961 0.101961
        }
      }
      geometry Cylinder {
        height 0.3
        radius 0.09
      }
    }
  ]
  name "solid(3)"
  boundingObject Cylinder {
    height 0.3
    radius 0.09
  }
}
Solid {
  translation -1.24 -0.25 0
  children [
    Shape {
      appearance Appearance {
        material Material {
          diffuseColor 0.101961 0.101961 0.101961
          emissiveColor 0.101961 0.101961 0.101961
        }
      }
      geometry Cylinder {
        height 0.3
        radius 0.09
      }
    }
  ]
  name "solid(4)"
  boundingObject Cylinder {
    height 0.3
    radius 0.09
  }
}
Solid {
  translation 0.84 -1.19 0
  children [
    Shape {
      appearance Appearance {
        material Material {
          diffuseColor 0.101961 0.101961 0.101961
          emissiveColor 0.101961 0.101961 0.101961
        }
      }
      geometry Cylinder {
        height 0.3
        radius 0.09
      }
    }
  ]
  name "solid(5)"
  boundingObject Cylinder {
    height 0.3
    radius 0.09
  }
}
Solid {
  translation 1.26 0.58 0
  children [
    Shape {
      appearance Appearance {
        material Material {
          diffuseColor 0.101961 0.101961 0.101961
          emissiveColor 0.101961 0.101961 0.101961
        }
      }
      geometry Cylinder {
        height 0.3
        radius 0.09
      }
    }
  ]
  name "solid(6)"
  boundingObject Cylinder {
    height 0.3
    radius 0.09
  }
}
Solid {
  translation -0.63 -1.23 0
  children [
    Shape {
      appearance Appearance {
        material Material {
          diffuseColor 0.101961 0.101961 0.101961
          emissiveColor 0.101961 0.101961 0.101961
        }
      }
      geometry Cylinder {
        height 0.3
        radius 0.09
      }
    }
  ]
  name "solid(7)"
  boundingObject Cylinder {
    height 0.3
    radius 0.09
  }
}
Robot {
  translation 0.3598988910720757 -0.14814687407824895 0.0500447805311341
  rotation 0.00010723073582507373 0.0002047864965363325 0.9999999732820296 2.1753465640252445
  children [
    TouchSensor {
      translation 0 0.083 -0.03
      children [
        Shape {
          geometry DEF BUMPER Box {
            size 0.01 0.01 0.01
          }
        }
      ]
      name "bumper_front"
      boundingObject USE BUMPER
    }
    TouchSensor {
      translation -0.0335 0.0659289 -0.03
      rotation 0 0 1 0.785398
      children [
        Shape {
          geometry DEF BUMPER Box {
            size 0.01 0.01 0.01
          }
        }
      ]
      name "bumper_left"
      boundingObject USE BUMPER
    }
    TouchSensor {
      translation 0.0335 0.065929 -0.03
      rotation 0 0 1 -0.785395307179586
      children [
        Shape {
          geometry DEF BUMPER Box {
            size 0.01 0.01 0.01
          }
        }
      ]
      name "bumper_right"
      boundingObject USE BUMPER
    }
    Compass {
      translation 0 0.04 0
    }
    GPS {
      translation 0 0.04 0.001
      children [
        Shape {
          appearance PBRAppearance {
          }
          geometry Capsule {
            height 0.005
            radius 0.005
          }
        }
      ]
    }
    DEF distance_sensor DistanceSensor {
      translation 0 0.0845 -0.01
      rotation 0.5773489358556708 0.5773509358554485 0.5773509358554485 2.0944
      children [
        DEF shape_distance_sensor Shape {
          appearance PBRAppearance {
            baseColor 0 0 1
            metalness 0
          }
          geometry Box {
            size 0.005 0.005 0.005
          }
        }
      ]
      name "d_front"
      boundingObject Box {
        size 0.005 0.005 0.005
      }
      lookupTable [
        0 0 0
        0.22 1000 0
      ]
      numberOfRays 2
      aperture 0.25
    }
    DEF distance_sensor DistanceSensor {
      translation 0.0300001 0.0745003 -0.01
      rotation 0.5773489358556708 0.5773509358554485 0.5773509358554485 2.0944
      children [
        DEF shape_distance_sensor Shape {
          appearance PBRAppearance {
            baseColor 0 0 1
            metalness 0
          }
          geometry Box {
            size 0.005 0.005 0.005
          }
        }
      ]
      name "d_right"
      boundingObject Box {
        size 0.005 0.005 0.005
      }
      lookupTable [
        0 0 0
        0.22 1000 0
      ]
      numberOfRays 2
      aperture 0.25
    }
    DEF distance_sensor DistanceSensor {
      translation 0.0450002 0.0445004 -0.00999996
      rotation 0.5773489358556708 0.5773509358554485 0.5773509358554485 1.98
      children [
        DEF shape_distance_sensor Shape {
          appearance PBRAppearance {
            baseColor 0 0 1
            metalness 0
          }
          geometry Box {
            size 0.005 0.005 0.005
          }
        }
      ]
      name "d_far_right"
      boundingObject Box {
        size 0.005 0.005 0.005
      }
      lookupTable [
        0 0 0
        0.18 1000 0
      ]
      numberOfRays 2
      aperture 0.25
    }
    DEF distance_sensor DistanceSensor {
      translation -0.03 0.0744999 -0.00999999
      rotation -0.5773489358556708 -0.5773509358554485 -0.5773509358554485 -2.094395307179586
      children [
        DEF shape_distance_sensor Shape {
          appearance PBRAppearance {
            baseColor 0 0 1
            metalness 0
          }
          geometry Box {
            size 0.005 0.005 0.005
          }
        }
      ]
      name "d_left"
      boundingObject Box {
        size 0.005 0.005 0.005
      }
      lookupTable [
        0 0 0
        0.22 1000 0
      ]
      numberOfRays 2
      aperture 0.25
    }
    DEF distance_sensor DistanceSensor {
      translation -0.045 0.0444999 -0.00999997
      rotation -0.5773489358556708 -0.5773509358554485 -0.5773509358554485 -2.2
      children [
        DEF shape_distance_sensor Shape {
          appearance PBRAppearance {
            baseColor 0 0 1
            metalness 0
          }
          geometry Box {
            size 0.005 0.005 0.005
          }
        }
      ]
      name "d_far_left"
      boundingObject Box {
        size 0.005 0.005 0.005
      }
      lookupTable [
        0 0 0
        0.18 1000 0
      ]
      numberOfRays 2
      aperture 0.25
    }
    Solid {
      translation 0 0.04 0.001
      rotation 0 0 1 1.5708
      children [
        USE shape_distance_sensor
      ]
      name "solid(2)"
    }
    DEF BodyShapeWithTransform Pose {
      translation 0 0.0415 -0.0176
      children [
        DEF Body Shape {
          appearance PBRAppearance {
            baseColor 1 0 0
            roughness 1
            metalness 0
          }
          geometry Cylinder {
            height 0.04
            radius 0.045
          }
        }
      ]
    }
    DEF wheel_joint HingeJoint {
      jointParameters HingeJointParameters {
        position 7.069461230613864e-13
        axis -1 0 0
        anchor -0.033 0.0425 -0.0353343
      }
      device [
        RotationalMotor {
          name "motor_1"
        }
      ]
      endPoint Solid {
        translation -0.033 0.0425 -0.0353343
        rotation -0.5708128258287837 0.5902085226214636 0.5708122438195837 4.207971096135417
        children [
          DEF shape_wheel Shape {
            appearance PBRAppearance {
              baseColor 0 0 1
              roughness 1
              metalness 0
            }
            geometry Cylinder {
              height 0.015
              radius 0.015
            }
          }
        ]
        boundingObject USE shape_wheel
        physics DEF wheel_physics Physics {
        }
      }
    }
    DEF wheel_joint HingeJoint {
      jointParameters HingeJointParameters {
        position 1.4256335131501333e-12
        axis -1 0 0
        anchor 0.033 0.0425 -0.0353343
      }
      device [
        RotationalMotor {
          name "motor_2"
        }
      ]
      endPoint Solid {
        translation 0.033 0.0425 -0.0353343
        rotation -0.15089670848218148 0.9769648986383017 0.15089655462566567 4.689087553612872
        children [
          DEF shape_wheel Shape {
            appearance PBRAppearance {
              baseColor 0 0 1
              roughness 1
              metalness 0
            }
            geometry Cylinder {
              height 0.015
              radius 0.015
            }
          }
        ]
        name "solid(1)"
        boundingObject USE shape_wheel
        physics USE wheel_physics
      }
    }
    DEF wheel_joint HingeJoint {
      jointParameters HingeJointParameters {
        position -3.8011552347567975e-13
        axis -1 0 0
        anchor -3.58483e-05 0.0104238 -0.0397
      }
      device [
        RotationalMotor {
          name "motor_3"
        }
      ]
      endPoint Solid {
        translation -3.58483e-05 0.0104238 -0.0397
        rotation 2.4707534218086525e-12 -0.9999999999999999 -2.470750902591919e-12 1.5707953071795862
        children [
          DEF shape_wheel Shape {
            appearance PBRAppearance {
              baseColor 0 0 1
              roughness 1
              metalness 0
            }
            geometry Cylinder {
              height 0.005
              radius 0.0105
            }
          }
        ]
        name "solid(3)"
        boundingObject USE shape_wheel
        physics USE wheel_physics
      }
    }
    DEF wheel_joint HingeJoint {
      jointParameters HingeJointParameters {
        position 1.4817256549693379e-10
        axis -1 0 0
        anchor 0 0.075 -0.0397
      }
      device [
        RotationalMotor {
          name "motor_4"
        }
      ]
      endPoint Solid {
        translation 3.72809e-05 0.0749015 -0.03969999999966437
        rotation -1.9262453154883546e-09 -0.9999999999999999 1.9262433514601413e-09 1.5707953071795862
        children [
          DEF shape_wheel Shape {
            appearance PBRAppearance {
              baseColor 0 0 1
              roughness 1
              metalness 0
            }
            geometry Cylinder {
              height 0.005
              radius 0.0105
            }
          }
        ]
        name "solid(4)"
        boundingObject USE shape_wheel
        physics USE wheel_physics
      }
    }
  ]
  boundingObject USE BodyShapeWithTransform
  physics Physics {
    density -1
    mass 1
  }
  controller "test_robot_controller_w2"
}
